Workbook

Sheet Despesas 2024
A1: ID | B1: Data | C1: Categoria | D1: Subcategoria | E1: Descrição | F1: Fornecedor | G1: Valor | H1: Departamento | I1: Centro de Custo | J1: Aprovador | K1: Status
A2: 1 | B2: 23/02/2024 | C2: TI | D2: Cloud | E2: Despesa 1 - Cloud | F2: Eta Supplies | G2: 489.33047 | H2: Diretoria | I2: CC-7698 | J2: Pedro Oliveira | K2: Pendente
A3: 2 | B3: 27/04/2024 | C3: Pessoal | D3: Salários | E3: Despesa 2 - Salários | F3: Delta Logistics | G3: 6273.7104 | H3: Diretoria | I3: CC-1141 | J3: Carla Souza | K3: Aprovado
A4: 3 | B4: 20/03/2024 | C4: Pessoal | D4: Benefícios | E4: Despesa 3 - Benefícios | F4: Zeta Consultoria | G4: 2378.9251 | H4: Operações | I4: CC-3754 | J4: Maria Silva | K4: Em Análise
A5: 4 | B5: 19/12/2024 | C5: Viagens | D5: Transporte | E5: Despesa 4 - Transporte | F5: Mu Airlines | G5: 3848.9468 | H5: Diretoria | I5: CC-8944 | J5: Carla Souza | K5: Rejeitado
A6: 5 | B6: 29/10/2024 | C6: Viagens | D6: Alimentação | E6: Despesa 5 - Alimentação | F6: Kappa Software | G6: 3358.7205 | H6: Financeiro | I6: CC-8970 | J6: Maria Silva | K6: Em Análise
A7: 6 | B7: 25/10/2024 | C7: Administrativo | D7: Jurídico | E7: Despesa 6 - Jurídico | F7: Gama Tecnologia | G7: 1635.7366 | H7: TI | I7: CC-5659 | J7: Pedro Oliveira | K7: Em Análise
A8: 7 | B8: 09/02/2024 | C8: Operacional | D8: Limpeza | E8: Despesa 7 - Limpeza | F8: Theta Energy | G8: 1823.3736 | H8: Financeiro | I8: CC-8258 | J8: Ana Costa | K8: Rejeitado
A9: 8 | B9: 06/09/2024 | C9: TI | D9: Software | E9: Despesa 8 - Software | F9: Xi Eventos | G9: 4452.0156 | H9: Marketing | I9: CC-1997 | J9: Pedro Oliveira | K9: Aprovado
A10: 9 | B10: 05/08/2024 | C10: TI | D10: Manutenção | E10: Despesa 9 - Manutenção | F10: Gama Tecnologia | G10: 2671.3545 | H10: Diretoria | I10: CC-6474 | J10: Carla Souza | K10: Em Análise
A11: 10 | B11: 08/03/2024 | C11: Operacional | D11: Manutenção | E11: Despesa 10 - Manutenção | F11: Tech Solutions Ltda | G11: 962.02501 | H11: Operações | I11: CC-1259 | J11: João Santos | K11: Rejeitado
A12: 11 | B12: 19/11/2024 | C12: Pessoal | D12: Benefícios | E12: Despesa 11 - Benefícios | F12: Tech Solutions Ltda | G12: 3434.8211 | H12: Diretoria | I12: CC-8029 | J12: Carla Souza | K12: Rejeitado
A13: 12 | B13: 15/07/2024 | C13: Pessoal | D13: Benefícios | E13: Despesa 12 - Benefícios | F13: Iota Telecom | G13: 3025.1432 | H13: Financeiro | I13: CC-2385 | J13: Carla Souza | K13: Pendente
... A56: 55 | B56: 17/08/2024 | C56: Pessoal | D56: Salários | E56: Despesa 55 - Salários | F56: Theta Energy | G56: 10720.065 | H56: TI | I56: CC-8331 | J56: Ana Costa | K56: Aprovado
A57: 56 | B57: 07/04/2024 | C57: Viagens | D57: Hospedagem | E57: Despesa 56 - Hospedagem | G57: 1080.6557 | H57: Vendas | I57: CC-6738 | J57: Ana Costa | K57: Em Análise
A58: 57 | B58: 15/06/2024 | C58: Infraestrutura | D58: Água | E58: Despesa 57 - Água | F58: Omicron Seguros | G58: 357.98699 | H58: Diretoria | I58: CC-9641 | J58: João Santos | K58: Aprovado
A59: 58 | B59: 21/08/2024 | C59: Operacional | D59: Materiais | E59: Despesa 58 - Materiais | F59: Delta Logistics | G59: 520.17635 | H59: RH | I59: CC-5351 | J59: Carla Souza | K59: Aprovado
A60: 59 | B60: 05/08/2024 | C60: Marketing | D60: Redes Sociais | E60: Despesa 59 - Redes Sociais | F60: Tech Solutions Ltda | G60: 1973.4428 | H60: Financeiro | I60: CC-7769 | J60: Carla Souza | K60: Em Análise
A61: 60 | B61: 05/10/2024 | C61: Pessoal | D61: Benefícios | E61: Despesa 60 - Benefícios | F61: Omicron Seguros | G61: 4764.0947 | H61: Operações | I61: CC-3924 | J61: João Santos | K61: Em Análise
A62: 61 | B62: 14/10/2024 | C62: Operacional | D62: Manutenção | E62: Despesa 61 - Manutenção | F62: Zeta Consultoria | G62: 2736.4428 | H62: RH | J62: Ana Costa | K62: Rejeitado
A63: 62 | B63: 21/04/2024 | C63: Infraestrutura | D63: Telefonia | E63: Despesa 62 - Telefonia | F63: Xi Eventos | G63: 4520.9219 | H63: Marketing | I63: CC-4101 | J63: Maria Silva | K63: Rejeitado
A64: 63 | B64: 24/06/2024 | C64: Infraestrutura | D64: Energia | E64: Despesa 63 - Energia | F64: Eta Supplies | G64: 2492.1504 | H64: Marketing | I64: CC-2901 | J64: Ana Costa | K64: Pendente
A65: 64 | B65: 23/03/2024 | C65: Marketing | D65: Eventos | E65: Despesa 64 - Eventos | F65: Eta Supplies | G65: 3296.7857 | H65: RH | I65: CC-8750 | J65: João Santos | K65: Pendente
A66: 65 | B66: 19/05/2024 | C66: Infraestrutura | D66: Energia | E66: Despesa 65 - Energia | F66: Zeta Consultoria | G66: 2834.4972 | H66: Vendas | I66: CC-9917 | J66: Carla Souza | K66: Em Análise
A67: 66 | B67: 12/01/2024 | C67: Administrativo | D67: Jurídico | E67: Despesa 66 - Jurídico | F67: Iota Telecom | G67: 3535.6937 | H67: RH | I67: CC-3525 | J67: Maria Silva | K67: Pendente
A68: 67 | B68: 2024-15-32 | C68: Administrativo | D68: Jurídico | E68: Despesa 67 - Jurídico | F68: Gama Tecnologia | G68: 2991.2814 | H68: Diretoria | I68: CC-7294 | J68: João Santos | K68: Em Análise
A69: 68 | B69: 02/07/2024 | C69: TI | D69: Manutenção | E69: Despesa 68 - Manutenção | F69: Eta Supplies | G69: 1816.0487 | H69: TI | I69: CC-8962 | J69: Carla Souza | K69: Em Análise
A70: 69 | B70: 08/10/2024 | C70: Marketing | D70: Publicidade Online | E70: Despesa 69 - Publicidade Online | F70: Tech Solutions Ltda | G70: 3363.2027 | H70: Financeiro | I70: CC-8301 | J70: Pedro Oliveira | K70: Aprovado
A71: 70 | B71: 17/10/2024 | C71: Administrativo | D71: Seguros | E71: Despesa 70 - Seguros | F71: Alpha Serviços | G71: 4762.2634 | H71: TI | I71: CC-3832 | J71: Maria Silva | K71: Aprovado
A72: 71 | B72: 16/09/2024 | C72: Pessoal | D72: Treinamento | E72: Despesa 71 - Treinamento | F72: Gama Tecnologia | G72: 1184.9042 | H72: Operações | I72: CC-1425 | J72: Maria Silva | K72: Rejeitado
A73: 72 | B73: 28/10/2024 | C73: Administrativo | D73: Jurídico | E73: Despesa 72 - Jurídico | F73: Epsilon Marketing | G73: 2891.8699 | H73: Financeiro | I73: CC-8787 | J73: Ana Costa | K73: Em Análise
A74: 73 | B74: 22/08/2024 | C74: Infraestrutura | D74: Água | E74: Despesa 73 - Água | F74: Tech Solutions Ltda | G74: 968.15432 | H74: Operações | I74: CC-4262 | J74: João Santos | K74: Em Análise
... A112: 111 | B112: 05/04/2024 | C112: Marketing | D112: Eventos | E112: Despesa 111 - Eventos | F112: Xi Eventos | G112: 409.94597 | H112: TI | I112: CC-2139 | J112: João Santos | K112: Em Análise
A113: 112 | B113: 10/08/2024 | C113: Viagens | D113: Transporte | E113: Despesa 112 - Transporte | G113: 384.54567 | H113: Financeiro | I113: CC-3487 | J113: Carla Souza | K113: Em Análise
A114: 113 | B114: 24/08/2024 | C114: Operacional | D114: Limpeza | E114: Despesa 113 - Limpeza | F114: Mu Airlines | G114: 1836.8015 | H114: Diretoria | I114: CC-5577 | J114: Maria Silva | K114: Rejeitado
A115: 114 | B115: 28/04/2024 | C115: Operacional | D115: Manutenção | E115: Despesa 114 - Manutenção | F115: Theta Energy | G115: 3892.1883 | H115: Marketing | I115: CC-4365 | J115: Carla Souza | K115: Em Análise
A116: 115 | B116: 17/10/2024 | C116: Viagens | D116: Transporte | E116: Despesa 115 - Transporte | F116: Omicron Seguros | G116: 1539.2785 | H116: Operações | I116: CC-1357 | J116: Ana Costa | K116: Aprovado
A117: 116 | B117: 12/06/2024 | C117: Operacional | D117: Manutenção | E117: Despesa 116 - Manutenção | F117: Lambda Hotels | G117: 4979.226 | H117: TI | I117: CC-3252 | J117: João Santos | K117: Aprovado
A118: 117 | B118: 20/12/2024 | C118: Marketing | D118: Material Gráfico | E118: Despesa 117 - Material Gráfico | F118: Mu Airlines | G118: 994.16483 | H118: Diretoria | I118: CC-8280 | J118: Carla Souza | K118: Em Análise
A119: 118 | B119: 16/03/2024 | C119: Marketing | D119: Publicidade Online | E119: Despesa 118 - Publicidade Online | F119: Beta Comercial | G119: 6265.4213 | H119: Financeiro | J119: Ana Costa | K119: Em Análise
...

Sheet Resumo por Categoria
A1: Categoria | B1: Total Despesas | C1: Qtd. Lançamentos | D1: Média | E1: % do Total
A2: Pessoal | B2: =SUMIF('Despesas 2024'!C:C,"Pessoal",'Despesas 2024'!G:G) -> 137361.08 | C2: =COUNTIF('Despesas 2024'!C:C,"Pessoal") -> 32 | D2: =B2/C2 -> 4292.5337 | E2: =B2/'Despesas 2024'!$G$202 -> 0.17070127
A3: Infraestrutura | B3: =SUMIF('Despesas 2024'!C:C,"Infraestrutura",'Despesas 2024'!G:G) -> 194535.09 | C3: =COUNTIF('Despesas 2024'!C:C,"Infraestrutura") -> 39 | D3: =B3/C3 -> 4988.0792 | E3: =B3/'Despesas 2024'!$G$202 -> 0.24175252
A4: Marketing | B4: =SUMIF('Despesas 2024'!C:C,"Marketing",'Despesas 2024'!G:G) -> 70415.662 | C4: =COUNTIF('Despesas 2024'!C:C,"Marketing") -> 24 | D4: =B4/C4 -> 2933.9859 | E4: =B4/'Despesas 2024'!$G$202 -> 0.087506907
A5: TI | B5: =SUMIF('Despesas 2024'!C:C,"TI",'Despesas 2024'!G:G) -> 44734.491 | C5: =COUNTIF('Despesas 2024'!C:C,"TI") -> 19 | D5: =B5/C5 -> 2354.4469 | E5: =B5/'Despesas 2024'!$G$202 -> 0.055592418
A6: Operacional | B6: =SUMIF('Despesas 2024'!C:C,"Operacional",'Despesas 2024'!G:G) -> 42521.28 | C6: =COUNTIF('Despesas 2024'!C:C,"Operacional") -> 22 | D6: =B6/C6 -> 1932.7855 | E6: =B6/'Despesas 2024'!$G$202 -> 0.052842019
A7: Administrativo | B7: =SUMIF('Despesas 2024'!C:C,"Administrativo",'Despesas 2024'!G:G) -> 157144.87 | C7: =COUNTIF('Despesas 2024'!C:C,"Administrativo") -> 29 | D7: =B7/C7 -> 5418.7887 | E7: =B7/'Despesas 2024'!$G$202 -> 0.19528698
A8: Viagens | B8: =SUMIF('Despesas 2024'!C:C,"Viagens",'Despesas 2024'!G:G) -> 155534.95 | C8: =COUNTIF('Despesas 2024'!C:C,"Viagens") -> 33 | D8: =B8/C8 -> 4713.1804 | E8: =B8/'Despesas 2024'!$G$202 -> 0.1932863
